[2022-11-12T05:26:55.869+0000] {taskinstance.py:1165} INFO - Dependencies all met for <TaskInstance: xcom_dag.xcom_task2 manual__2022-11-12T05:26:44.131837+00:00 [queued]>
[2022-11-12T05:26:56.058+0000] {taskinstance.py:1165} INFO - Dependencies all met for <TaskInstance: xcom_dag.xcom_task2 manual__2022-11-12T05:26:44.131837+00:00 [queued]>
[2022-11-12T05:26:56.061+0000] {taskinstance.py:1362} INFO - 
--------------------------------------------------------------------------------
[2022-11-12T05:26:56.071+0000] {taskinstance.py:1363} INFO - Starting attempt 1 of 1
[2022-11-12T05:26:56.087+0000] {taskinstance.py:1364} INFO - 
--------------------------------------------------------------------------------
[2022-11-12T05:26:56.188+0000] {taskinstance.py:1383} INFO - Executing <Task(PythonOperator): xcom_task2> on 2022-11-12 05:26:44.131837+00:00
[2022-11-12T05:26:56.244+0000] {standard_task_runner.py:54} INFO - Started process 1852 to run task
[2022-11-12T05:26:56.285+0000] {standard_task_runner.py:82} INFO - Running: ['***', 'tasks', 'run', 'xcom_dag', 'xcom_task2', 'manual__2022-11-12T05:26:44.131837+00:00', '--job-id', '24', '--raw', '--subdir', 'DAGS_FOLDER/xcom_dag.py', '--cfg-path', '/tmp/tmpj34ganbl']
[2022-11-12T05:26:56.306+0000] {standard_task_runner.py:83} INFO - Job 24: Subtask xcom_task2
[2022-11-12T05:26:56.327+0000] {dagbag.py:525} INFO - Filling up the DagBag from /opt/***/dags/xcom_dag.py
[2022-11-12T05:26:57.212+0000] {task_command.py:384} INFO - Running <TaskInstance: xcom_dag.xcom_task2 manual__2022-11-12T05:26:44.131837+00:00 [running]> on host 4e1173cf24e4
[2022-11-12T05:26:57.992+0000] {taskinstance.py:1592} INFO - Exporting the following env vars:
AIRFLOW_CTX_DAG_OWNER=***
AIRFLOW_CTX_DAG_ID=xcom_dag
AIRFLOW_CTX_TASK_ID=xcom_task2
AIRFLOW_CTX_EXECUTION_DATE=2022-11-12T05:26:44.131837+00:00
AIRFLOW_CTX_TRY_NUMBER=1
AIRFLOW_CTX_DAG_RUN_ID=manual__2022-11-12T05:26:44.131837+00:00
[2022-11-12T05:26:57.996+0000] {taskinstance.py:1851} ERROR - Task failed with exception
Traceback (most recent call last):
  File "/home/airflow/.local/lib/python3.7/site-packages/airflow/operators/python.py", line 175, in execute
    return_value = self.execute_callable()
  File "/home/airflow/.local/lib/python3.7/site-packages/airflow/operators/python.py", line 193, in execute_callable
    return self.python_callable(*self.op_args, **self.op_kwargs)
  File "/opt/airflow/dags/xcom_dag.py", line 14, in greet
    name= ti.xcoms_pull(task_ids="xcom_task1")
AttributeError: 'TaskInstance' object has no attribute 'xcoms_pull'
[2022-11-12T05:26:58.053+0000] {taskinstance.py:1406} INFO - Marking task as FAILED. dag_id=xcom_dag, task_id=xcom_task2, execution_date=20221112T052644, start_date=20221112T052655, end_date=20221112T052658
[2022-11-12T05:26:58.118+0000] {standard_task_runner.py:107} ERROR - Failed to execute job 24 for task xcom_task2 ('TaskInstance' object has no attribute 'xcoms_pull'; 1852)
[2022-11-12T05:26:58.191+0000] {local_task_job.py:164} INFO - Task exited with return code 1
[2022-11-12T05:26:58.368+0000] {local_task_job.py:273} INFO - 0 downstream tasks scheduled from follow-on schedule check
